<?xml version="1.0"?>

<!-- This URDF was automatically created by SolidWorks to URDF Exporter! Originally created by Stephen Brawner (brawner@gmail.com) 
     Commit Version: 1.6.0-1-g15f4949  Build Version: 1.6.7594.29634
     For more information, please see http://wiki.ros.org/sw_urdf_exporter -->
<robot name="cr7_robot">
  <link 
     name="world">
     <visual>
      <origin
        xyz="0 0 0"
        rpy="0 0 0" />
      <geometry>
        <box size="0.0001 0.0001 0.0001" />
      </geometry>
    </visual>
  </link>
  
  <link
    name="base_link">
    <inertial>
      <origin
        xyz="-7.75881826404344E-06 0.00191109737802069 0.0289949710713939"
        rpy="0 0 0" />
      <mass
        value="0.908795453638862" />
      <inertia
        ixx="0.00145446136430631"
        ixy="4.10411509661615E-08"
        ixz="-1.83603068187756E-07"
        iyy="0.00134497445765809"
        iyz="-6.24662501711042E-06"
        izz="0.00215495523232905" />
    </inertial>
    <visual>
      <origin
        xyz="0 0 0"
        rpy="0 0 0" />
      <geometry>
        <mesh
          filename="/home/taqiaden/GraspAgent/GraspAgent_2/kinematic_utils/cr7_speed/base_link0.STL" />
      </geometry>
      <material
        name="">
        <color
          rgba="0.792156862745098 0.819607843137255 0.933333333333333 1" />
      </material>
    </visual>
    <collision>
      <origin
        xyz="0 0 0"
        rpy="0 0 0" />
      <geometry>
        <mesh
          filename="/home/taqiaden/GraspAgent/GraspAgent_2/kinematic_utils/cr7_speed/base_link0.STL" />
      </geometry>
    </collision>
  </link>
  <joint name="world2arm_fixed" type="fixed">
    <origin xyz="0 0 0" rpy="0 0 0"/>
    <parent link="world"/>
    <child  link="base_link"/>
  </joint>

  <link
    name="Link1">
    <inertial>
      <origin
        xyz="2.42083892138974E-07 -0.00325669708857515 -0.00767435596457115"
        rpy="0 0 0" />
      <mass
        value="1.6123155679073" />
      <inertia
        ixx="0.00291211377650885"
        ixy="-7.47419584239082E-09"
        ixz="1.94780650217368E-08"
        iyy="0.00281918869862419"
        iyz="0.000440963272842605"
        izz="0.00328358201221721" />
    </inertial>
    <visual>
      <origin
        xyz="0 0 0"
        rpy="0 0 0" />
      <geometry>
        <mesh
          filename="/home/taqiaden/GraspAgent/GraspAgent_2/kinematic_utils/cr7_speed/J1.STL" />
      </geometry>
      <material
        name="">
        <color
          rgba="0.792156862745098 0.819607843137255 0.933333333333333 1" />
      </material>
    </visual>
    <collision>
      <origin
        xyz="0 0 0"
        rpy="0 0 0" />
      <geometry>
        <mesh
          filename="/home/taqiaden/GraspAgent/GraspAgent_2/kinematic_utils/cr7_speed/J1.STL" />
      </geometry>
    </collision>
  </link>
  <joint
    name="joint1"
    type="revolute">
    <origin
      xyz="0 0 0.147"
      rpy="0 0 0" />
    <parent
      link="base_link" />
    <child
      link="Link1" />
    <axis
      xyz="0 0 1" />
    <limit
      lower="-6.27"
      upper="6.27"
      effort="300"
      velocity="100" />
  </joint>
  <link
    name="Link2">
    <inertial>
      <origin
        xyz="-0.188500103625708 -7.46110088887752E-07 0.142319304936727"
        rpy="0 0 0" />
      <mass
        value="5.28764336862191" />
      <inertia
        ixx="0.00860086052884714"
        ixy="3.30521626209469E-09"
        ixz="-4.99788929762243E-09"
        iyy="0.0181761454963347"
        iyz="-1.56481985512198E-08"
        izz="0.0189188799857172" />
    </inertial>
    <visual>
      <origin
        xyz="0 0 0"
        rpy="0 0 0" />
      <geometry>
        <mesh
          filename="/home/taqiaden/GraspAgent/GraspAgent_2/kinematic_utils/cr7_speed/J2.STL" />
      </geometry>
      <material
        name="">
        <color
          rgba="0.792156862745098 0.819607843137255 0.933333333333333 1" />
      </material>
    </visual>
    <collision>
      <origin
        xyz="0 0 0"
        rpy="0 0 0" />
      <geometry>
        <mesh
          filename="/home/taqiaden/GraspAgent/GraspAgent_2/kinematic_utils/cr7_speed/J2.STL" />
      </geometry>
    </collision>
  </link>
  <joint
    name="joint2"
    type="revolute">
    <origin
      xyz="0 0 0"
      rpy="-1.57080420997483 1.57079631189374 -3.14158502419526" />
    <parent
      link="Link1" />
    <child
      link="Link2" />
    <axis
      xyz="0 0 1" />
    <limit
      lower="-6.27"
      upper="6.27"
      effort="300"
      velocity="100" />
  </joint>
  <link
    name="Link3">
    <inertial>
      <origin
        xyz="-0.129084033261017 0.000409825982416691 -0.0024891265183234"
        rpy="0 0 0" />
      <mass
        value="2.64536322797469" />
      <inertia
        ixx="0.00313429310657436"
        ixy="8.58567214179718E-06"
        ixz="0.0001236219933347"
        iyy="0.00583755221707048"
        iyz="-3.84538201491329E-07"
        izz="0.00609610718076456" />
    </inertial>
    <visual>
      <origin
        xyz="0 0 0"
        rpy="0 0 0" />
      <geometry>
        <mesh
          filename="/home/taqiaden/GraspAgent/GraspAgent_2/kinematic_utils/cr7_speed/J3.STL" />
      </geometry>
      <material
        name="">
        <color
          rgba="0.792156862745098 0.819607843137255 0.933333333333333 1" />
      </material>
    </visual>
    <collision>
      <origin
        xyz="0 0 0"
        rpy="0 0 0" />
      <geometry>
        <mesh
          filename="/home/taqiaden/GraspAgent/GraspAgent_2/kinematic_utils/cr7_speed/J3.STL" />
      </geometry>
    </collision>
  </link>
  <joint
    name="joint3"
    type="revolute">
    <origin
      xyz="-0.377 0 0.025"
      rpy="0 0 0" />
    <parent
      link="Link2" />
    <child
      link="Link3" />
    <axis
      xyz="0 0 1" />
    <limit
      lower="-2.79"
      upper="2.79"
      effort="300"
      velocity="100" />
  </joint>
  <link
    name="Link4">
    <inertial>
      <origin
        xyz="-0.00098049161725656 -0.00207570116557487 -0.00155508673006152"
        rpy="0 0 0" />
      <mass
        value="0.670573134819647" />
      <inertia
        ixx="0.000669371731621344"
        ixy="-5.32805461934157E-08"
        ixz="3.52586632357936E-07"
        iyy="0.000654228488306913"
        iyz="0.000110801103983602"
        izz="0.000653654751027863" />
    </inertial>
    <visual>
      <origin
        xyz="0 0 0"
        rpy="0 0 0" />
      <geometry>
        <mesh
          filename="/home/taqiaden/GraspAgent/GraspAgent_2/kinematic_utils/cr7_speed/J4.STL" />
      </geometry>
      <material
        name="">
        <color
          rgba="0.792156862745098 0.819607843137255 0.933333333333333 1" />
      </material>
    </visual>
    <collision>
      <origin
        xyz="0 0 0"
        rpy="0 0 0" />
      <geometry>
        <mesh
          filename="/home/taqiaden/GraspAgent/GraspAgent_2/kinematic_utils/cr7_speed/J4.STL" />
      </geometry>
    </collision>
  </link>
  <joint
    name="joint4"
    type="revolute">
    <origin
      xyz="-0.306999999999969 0 0.116"
      rpy="0 0 -1.57079677671549" />
    <parent
      link="Link3" />
    <child
      link="Link4" />
    <axis
      xyz="0 0 1" />
    <limit
      lower="-6.27"
      upper="6.27"
      effort="300"
      velocity="100" />
  </joint>
  <link
    name="Link5">
    <inertial>
      <origin
        xyz="-0.00139233872001005 -0.00449255371185306 -0.00130478579616922"
        rpy="0 0 0" />
      <mass
        value="0.725828190120638" />
      <inertia
        ixx="0.00073002940905788"
        ixy="1.46530702319641E-07"
        ixz="-1.21461719923983E-07"
        iyy="0.000710023403641111"
        iyz="-0.000119103387993809"
        izz="0.000712169450212708" />
    </inertial>
    <visual>
      <origin
        xyz="0 0 0"
        rpy="0 0 0" />
      <geometry>
        <mesh
          filename="/home/taqiaden/GraspAgent/GraspAgent_2/kinematic_utils/cr7_speed/J5.STL" />
      </geometry>
      <material
        name="">
        <color
          rgba="0.792156862745098 0.819607843137255 0.933333333333333 1" />
      </material>
    </visual>
    <collision>
      <origin
        xyz="0 0 0"
        rpy="0 0 0" />
      <geometry>
        <mesh
          filename="/home/taqiaden/GraspAgent/GraspAgent_2/kinematic_utils/cr7_speed/J5.STL" />
      </geometry>
    </collision>
  </link>
  <joint
    name="joint5"
    type="revolute">
    <origin
      xyz="0 -0.116 0"
      rpy="1.5707963267949 0 0" />
    <parent
      link="Link4" />
    <child
      link="Link5" />
    <axis
      xyz="0 0 1" />
    <limit
      lower="-6.27"
      upper="6.27"
      effort="300"
      velocity="100" />
  </joint>
  <link
    name="Link6">
    <inertial>
      <origin
        xyz="-0.00134099075400824 9.61028193323665E-05 -0.0192856508049091"
        rpy="0 0 0" />
      <mass
        value="0.157885328078873" />
      <inertia
        ixx="7.80450650011017E-05"
        ixy="3.56327806101489E-09"
        ixz="-3.98217377472077E-11"
        iyy="7.91678595101433E-05"
        iyz="-1.3821786505554E-07"
        izz="0.000129505866960959" />
    </inertial>
    <visual>
      <origin
        xyz="0 0 0"
        rpy="0 0 0" />
      <geometry>
        <mesh
          filename="/home/taqiaden/GraspAgent/GraspAgent_2/kinematic_utils/cr7_speed/J6.STL" />
      </geometry>
      <material
        name="">
        <color
          rgba="0.792156862745098 0.819607843137255 0.933333333333333 1" />
      </material>
    </visual>
    <collision>
      <origin
        xyz="0 0 0"
        rpy="0 0 0" />
      <geometry>
        <mesh
          filename="/home/taqiaden/GraspAgent/GraspAgent_2/kinematic_utils/cr7_speed/J6.STL" />
      </geometry>
    </collision>
  </link>
  <joint
    name="joint6"
    type="revolute">
    <origin
      xyz="0 0.104999656773681 0"
      rpy="-1.5707963267949 0 0" />
    <parent
      link="Link5" />
    <child
      link="Link6" />
    <axis
      xyz="0 0 1" />
    <limit
      lower="-6.27"
      upper="6.27"
      effort="300"
      velocity="100" />
  </joint>

  <link name="box_link">
    <inertial>
      <origin xyz="0 0 0" rpy="0 0 0"/>
      <mass value="0.1"/>
      <inertia ixx="0.001" ixy="0" ixz="0" iyy="0.001" iyz="0" izz="0.001"/>
    </inertial>
    <visual>
      <origin xyz="0 0 0" rpy="0 0 0"/>
      <geometry>
        <box size="0.035 0.09 0.01"/>
      </geometry>
      <material name="">
        <color rgba="0.8 0.2 0.2 1"/>
      </material>
    </visual>
    <collision>
      <origin xyz="0 0 0" rpy="0 0 0"/>
      <geometry>
        <box size="0.035 0.09 0.01"/>
      </geometry>
    </collision>
  </link>
  
  <joint name="box_joint" type="fixed">
    <origin xyz="0.05196 0.03 0" rpy="0 0 2.09"/>
    <parent link="Link6"/>
    <child link="box_link"/>
  </joint>
   
 <link
    name="hand_base_link">
    <inertial>
      <origin
        xyz="0.0 -0.0 0.0"
        rpy="0 0 0" />
      <mass
        value="0.0441995346439479" />
      <inertia
        ixx="9.94852342811219E-06"
        ixy="-1.10569847241101E-07"
        ixz="-9.13569873502352E-08"
        iyy="1.66207143987831E-05"
        iyz="-8.71780838551483E-09"
        izz="7.91121496969452E-06" />
    </inertial>
    <visual>
      <origin
        xyz="-0.2048 0.241 -0.006"
        rpy="0 0 0" />
      <geometry>
        <mesh
          filename="/home/taqiaden/GraspAgent/GraspAgent_2/kinematic_utils/cr7_speed/hand_base_link.STL" />
      </geometry>
      <material
        name="">
        <color
          rgba="0.752941176470588 0.752941176470588 0.752941176470588 1" />
      </material>
    </visual>
    <collision>
      <origin
        xyz="-0.2048 0.241 -0.006"
        rpy="0 0 0" />
      <geometry>
        <mesh
          filename="/home/taqiaden/GraspAgent/GraspAgent_2/kinematic_utils/cr7_speed/hand_base_link.STL" />
      </geometry>
    </collision>
  </link>
  <joint name="RArm6_to_hand_fixed" type="fixed">
    <origin 
        xyz="0 0.0 0.01" 
        rpy="-1.57 0 2.09"/>
    <parent link="Link6"/>
    <child  link="hand_base_link"/>
  </joint>

  <link
    name="RLF_joint1_link">
    <inertial>
      <origin
        xyz="-0.00052376 -0.019871 -0.0057348"
        rpy="0 0 0" />
      <mass
        value="0.0086971" />
      <inertia
        ixx="1.7729E-06"
        ixy="-5.2252E-08"
        ixz="2.8617E-10"
        iyy="5.6127E-07"
        iyz="6.3403E-09"
        izz="1.5998E-06" />
    </inertial>
    <visual>
      <origin
        xyz="0 0 0"
        rpy="0 0 0" />
      <geometry>
        <mesh
          filename="/home/taqiaden/GraspAgent/GraspAgent_2/kinematic_utils/cr7_speed/RLF_joint1_link.STL" />
      </geometry>
      <material
        name="">
        <color
          rgba="0.75294 0.75294 0.75294 1" />
      </material>
    </visual>
    <collision>
      <origin
        xyz="0 0 0"
        rpy="0 0 0" />
      <geometry>
        <mesh
          filename="/home/taqiaden/GraspAgent/GraspAgent_2/kinematic_utils/cr7_speed/RLF_joint1_link.STL" />
      </geometry>
    </collision>
  </link>
  <joint
    name="RLF_joint1"
    type="revolute">
    <origin
      xyz="-0.00906  -0.1314   -0.036054"
      rpy="0.069813 0 0" />
    <parent
      link="hand_base_link" />
    <child
      link="RLF_joint1_link" />
    <axis
      xyz="0 0 1" />
    <limit
      lower="0"
      upper="1.57"
      effort="0"
      velocity="0" />
  </joint>
  <link
    name="RLF_joint2_link">
    <inertial>
      <origin
        xyz="0.0011821 -0.012573 -0.0035798"
        rpy="0 0 0" />
      <mass
        value="0.0054225" />
      <inertia
        ixx="6.9578E-07"
        ixy="4.7421E-08"
        ixz="-1.9286E-09"
        iyy="3.0909E-07"
        iyz="6.2034E-09"
        izz="5.9241E-07" />
    </inertial>
    <visual>
      <origin
        xyz="0 0 0"
        rpy="0 0 0" />
      <geometry>
        <mesh
          filename="/home/taqiaden/GraspAgent/GraspAgent_2/kinematic_utils/cr7_speed/RLF_joint2_link.STL" />
      </geometry>
      <material
        name="">
        <color
          rgba="0.75294 0.75294 0.75294 1" />
      </material>
    </visual>
    <collision>
      <origin
        xyz="0 0 0"
        rpy="0 0 0" />
      <geometry>
        <mesh
          filename="/home/taqiaden/GraspAgent/GraspAgent_2/kinematic_utils/cr7_speed/RLF_joint2_link.STL" />
      </geometry>
    </collision>
  </link>
  <joint
    name="RLF_joint2"
    type="revolute">
    <origin
      xyz="0 -0.044835 -0.0022002"
      rpy="0 0 0" />
    <parent
      link="RLF_joint1_link" />
    <child
      link="RLF_joint2_link" />
    <axis
      xyz="0 0 1" />
    <limit
      lower="0"
      upper="1.57"
      effort="0"
      velocity="0" />
  </joint>
  <link
    name="RLF_joint3_link">
    <inertial>
      <origin
        xyz="0.000229199725927387 -0.0173318014256736 -0.0036024183770771"
        rpy="0 0 0" />
      <mass
        value="0.00359542883058394" />
      <inertia
        ixx="2.43208335594901E-07"
        ixy="1.66417995784244E-09"
        ixz="-1.51914918252211E-12"
        iyy="9.67131689205526E-08"
        iyz="2.50977743703426E-11"
        izz="1.88803036320957E-07" />
    </inertial>
    <visual>
      <origin
        xyz="0 0 0"
        rpy="0 0 0" />
      <geometry>
        <mesh
          filename="/home/taqiaden/GraspAgent/GraspAgent_2/kinematic_utils/cr7_speed/RLF_joint3_link.STL" />
      </geometry>
      <material
        name="">
        <color
          rgba="0.752941176470588 0.752941176470588 0.752941176470588 1" />
      </material>
    </visual>
    <collision>
      <origin
        xyz="0 0 0"
        rpy="0 0 0" />
      <geometry>
        <mesh
          filename="/home/taqiaden/GraspAgent/GraspAgent_2/kinematic_utils/cr7_speed/RLF_joint3_link.STL" />
      </geometry>
    </collision>
  </link>
  <joint
    name="RLF_joint3"
    type="revolute">
    <origin
      xyz="0.0019613 -0.024923 0.00010298"
      rpy="0 0 0" />
    <parent
      link="RLF_joint2_link" />
    <child
      link="RLF_joint3_link" />
    <axis
      xyz="0 0 1" />
    <limit
      lower="0"
      upper="1.57"
      effort="0"
      velocity="0" />
  </joint>
  <link
    name="RRF_joint1_link">
    <inertial>
      <origin
        xyz="-0.00052377 -0.019871 -0.0057348"
        rpy="0 0 0" />
      <mass
        value="0.0086971" />
      <inertia
        ixx="1.7729E-06"
        ixy="-5.2252E-08"
        ixz="2.8689E-10"
        iyy="5.6127E-07"
        iyz="6.3411E-09"
        izz="1.5998E-06" />
    </inertial>
    <visual>
      <origin
        xyz="0 0 0"
        rpy="0 0 0" />
      <geometry>
        <mesh
          filename="/home/taqiaden/GraspAgent/GraspAgent_2/kinematic_utils/cr7_speed/RRF_joint1_link.STL" />
      </geometry>
      <material
        name="">
        <color
          rgba="0.75294 0.75294 0.75294 1" />
      </material>
    </visual>
    <collision>
      <origin
        xyz="0 0 0"
        rpy="0 0 0" />
      <geometry>
        <mesh
          filename="/home/taqiaden/GraspAgent/GraspAgent_2/kinematic_utils/cr7_speed/RRF_joint1_link.STL" />
      </geometry>
    </collision>
  </link>
  <joint
    name="RRF_joint1"
    type="revolute">
    <origin
      xyz="-0.00906   -0.1357    -0.0121806"
      rpy="0.034907 0 0" />
    <parent
      link="hand_base_link" />
    <child
      link="RRF_joint1_link" />
    <axis
      xyz="0 0 1" />
    <limit
      lower="0"
      upper="1.57"
      effort="0"
      velocity="0" />
  </joint>
  <link
    name="RRF_joint2_link">
    <inertial>
      <origin
        xyz="0.0011456 -0.012552 -0.0035807"
        rpy="0 0 0" />
      <mass
        value="0.0053861" />
      <inertia
        ixx="6.9572E-07"
        ixy="4.7421E-08"
        ixz="-1.9289E-09"
        iyy="3.0903E-07"
        iyz="6.2036E-09"
        izz="5.9235E-07" />
    </inertial>
    <visual>
      <origin
        xyz="0 0 0"
        rpy="0 0 0" />
      <geometry>
        <mesh
          filename="/home/taqiaden/GraspAgent/GraspAgent_2/kinematic_utils/cr7_speed/RRF_joint2_link.STL" />
      </geometry>
      <material
        name="">
        <color
          rgba="0.75294 0.75294 0.75294 1" />
      </material>
    </visual>
    <collision>
      <origin
        xyz="0 0 0"
        rpy="0 0 0" />
      <geometry>
        <mesh
          filename="/home/taqiaden/GraspAgent/GraspAgent_2/kinematic_utils/cr7_speed/RRF_joint2_link.STL" />
      </geometry>
    </collision>
  </link>
  <joint
    name="RRF_joint2"
    type="revolute">
    <origin
      xyz="0 -0.044835 -0.0022002"      
      rpy="0 0 0" />
    <parent
      link="RRF_joint1_link" />
    <child
      link="RRF_joint2_link" />
    <axis
      xyz="0 0 1" />
    <limit
      lower="0"
      upper="1.57"
      effort="0"
      velocity="0" />
  </joint>
  <link
    name="RRF_joint3_link">
    <inertial>
      <origin
        xyz="0.00022922 -0.017332 -0.0036024"
        rpy="0 0 0" />
      <mass
        value="0.0035954" />
      <inertia
        ixx="2.4321E-07"
        ixy="1.6641E-09"
        ixz="-1.354E-12"
        iyy="9.6713E-08"
        iyz="2.5075E-11"
        izz="1.888E-07" />
    </inertial>
    <visual>
      <origin
        xyz="0 0 0"
        rpy="0 0 0" />
      <geometry>
        <mesh
          filename="/home/taqiaden/GraspAgent/GraspAgent_2/kinematic_utils/cr7_speed/RRF_joint3_link.STL" />
      </geometry>
      <material
        name="">
        <color
          rgba="0.75294 0.75294 0.75294 1" />
      </material>
    </visual>
    <collision>
      <origin
        xyz="0 0 0"
        rpy="0 0 0" />
      <geometry>
        <mesh
          filename="/home/taqiaden/GraspAgent/GraspAgent_2/kinematic_utils/cr7_speed/RRF_joint3_link.STL" />
      </geometry>
    </collision>
  </link>
  <joint
    name="RRF_joint3"
    type="revolute">
    <origin
      xyz="0.0019613 -0.024923 0.00010298"      
      rpy="0 0 0" />
    <parent
      link="RRF_joint2_link" />
    <child
      link="RRF_joint3_link" />
    <axis
      xyz="0 0 1" />
    <limit
      lower="0"
      upper="1.57"
      effort="0"
      velocity="0" />
  </joint>
  <link
    name="RMF_joint1_link">
    <inertial>
      <origin
        xyz="-0.00052377 -0.019871 -0.0057348"
        rpy="0 0 0" />
      <mass
        value="0.0086971" />
      <inertia
        ixx="1.7729E-06"
        ixy="-5.2251E-08"
        ixz="2.872E-10"
        iyy="5.6127E-07"
        iyz="6.3417E-09"
        izz="1.5998E-06" />
    </inertial>
    <visual>
      <origin
        xyz="0 0 0"
        rpy="0 0 0" />
      <geometry>
        <mesh
          filename="/home/taqiaden/GraspAgent/GraspAgent_2/kinematic_utils/cr7_speed/RMF_joint1_link.STL" />
      </geometry>
      <material
        name="">
        <color
          rgba="0.75294 0.75294 0.75294 1" />
      </material>
    </visual>
    <collision>
      <origin
        xyz="0 0 0"
        rpy="0 0 0" />
      <geometry>
        <mesh
          filename="/home/taqiaden/GraspAgent/GraspAgent_2/kinematic_utils/cr7_speed/RMF_joint1_link.STL" />
      </geometry>
    </collision>
  </link>
  <joint
    name="RMF_joint1"
    type="revolute">
    <origin
      xyz="-0.00906 -0.14038  0.0107"
      rpy="0 0 0" />
    <parent
      link="hand_base_link" />
    <child
      link="RMF_joint1_link" />
    <axis
      xyz="0 0 1" />
    <limit
      lower="0"
      upper="1.57"
      effort="0"
      velocity="0" />
  </joint>
  <link
    name="RMF_joint2_link">
    <inertial>
      <origin
        xyz="0.001287 -0.012538 -0.0035807"
        rpy="0 0 0" />
      <mass
        value="0.0053861" />
      <inertia
        ixx="6.946E-07"
        ixy="5.1767E-08"
        ixz="-1.9989E-09"
        iyy="3.1014E-07"
        iyz="6.179E-09"
        izz="5.9235E-07" />
    </inertial>
    <visual>
      <origin
        xyz="0 0 0"
        rpy="0 0 0" />
      <geometry>
        <mesh
          filename="/home/taqiaden/GraspAgent/GraspAgent_2/kinematic_utils/cr7_speed/RMF_joint2_link.STL" />
      </geometry>
      <material
        name="">
        <color
          rgba="0.75294 0.75294 0.75294 1" />
      </material>
    </visual>
    <collision>
      <origin
        xyz="0 0 0"
        rpy="0 0 0" />
      <geometry>
        <mesh
          filename="/home/taqiaden/GraspAgent/GraspAgent_2/kinematic_utils/cr7_speed/RMF_joint2_link.STL" />
      </geometry>
    </collision>
  </link>
  <joint
    name="RMF_joint2"
    type="revolute">
    <origin
      xyz="0 -0.044835 -0.0022002"
      rpy="0 0 -0.011273" />
    <parent
      link="RMF_joint1_link" />
    <child
      link="RMF_joint2_link" />
    <axis
      xyz="0 0 1" />
    <limit
      lower="0"
      upper="1.57"
      effort="0"
      velocity="0" />
  </joint>
  <link
    name="RMF_joint3_link">
    <inertial>
      <origin
        xyz="0.00015719 -0.017333 -0.0036024"
        rpy="0 0 0" />
      <mass
        value="0.0035954" />
      <inertia
        ixx="2.4322E-07"
        ixy="1.0553E-09"
        ixz="-9.9023E-13"
        iyy="9.6701E-08"
        iyz="2.4593E-11"
        izz="1.888E-07" />
    </inertial>
    <visual>
      <origin
        xyz="0 0 0"
        rpy="0 0 0" />
      <geometry>
        <mesh
          filename="/home/taqiaden/GraspAgent/GraspAgent_2/kinematic_utils/cr7_speed/RMF_joint3_link.STL" />
      </geometry>
      <material
        name="">
        <color
          rgba="0.75294 0.75294 0.75294 1" />
      </material>
    </visual>
    <collision>
      <origin
        xyz="0 0 0"
        rpy="0 0 0" />
      <geometry>
        <mesh
          filename="/home/taqiaden/GraspAgent/GraspAgent_2/kinematic_utils/cr7_speed/RMF_joint3_link.STL" />
      </geometry>
    </collision>
  </link>
  <joint
    name="RMF_joint3"
    type="revolute">
    <origin
      xyz="0.0022421 -0.0249 0.00010298"
      rpy="0 0 0.015427" />
    <parent
      link="RMF_joint2_link" />
    <child
      link="RMF_joint3_link" />
    <axis
      xyz="0 0 1" />
    <limit
      lower="0"
      upper="1.57"
      effort="0"
      velocity="0" />
  </joint>
  <link
    name="RFF_joint1_link">
    <inertial>
      <origin
        xyz="-0.00052376 -0.019871 -0.0057348"
        rpy="0 0 0" />
      <mass
        value="0.0086971" />
      <inertia
        ixx="1.7729E-06"
        ixy="-5.2252E-08"
        ixz="2.8671E-10"
        iyy="5.6127E-07"
        iyz="6.3417E-09"
        izz="1.5998E-06" />
    </inertial>
    <visual>
      <origin
        xyz="0 0 0"
        rpy="0 0 0" />
      <geometry>
        <mesh
          filename="/home/taqiaden/GraspAgent/GraspAgent_2/kinematic_utils/cr7_speed/RFF_joint1_link.STL" />
      </geometry>
      <material
        name="">
        <color
          rgba="0.75294 0.75294 0.75294 1" />
      </material>
    </visual>
    <collision>
      <origin
        xyz="0 0 0"
        rpy="0 0 0" />
      <geometry>
        <mesh
          filename="/home/taqiaden/GraspAgent/GraspAgent_2/kinematic_utils/cr7_speed/RFF_joint1_link.STL" />
      </geometry>
    </collision>
  </link>
  <joint
    name="RFF_joint1"
    type="revolute">
    <origin
      xyz="-0.00906  -0.13708   0.034085"
      rpy="-0.034907 0 0" />
    <parent
      link="hand_base_link" />
    <child
      link="RFF_joint1_link" />
    <axis
      xyz="0 0 1" />
    <limit
      lower="0"
      upper="1.57"
      effort="0"
      velocity="0" />
  </joint>
  <link
    name="RFF_joint2_link">
    <inertial>
      <origin
        xyz="0.0011455 -0.012552 -0.0035807"
        rpy="0 0 0" />
      <mass
        value="0.0053861" />
      <inertia
        ixx="6.9572E-07"
        ixy="4.742E-08"
        ixz="-1.9293E-09"
        iyy="3.0903E-07"
        iyz="6.2014E-09"
        izz="5.9235E-07" />
    </inertial>
    <visual>
      <origin
        xyz="0 0 0"
        rpy="0 0 0" />
      <geometry>
        <mesh
          filename="/home/taqiaden/GraspAgent/GraspAgent_2/kinematic_utils/cr7_speed/RFF_joint2_link.STL" />
      </geometry>
      <material
        name="">
        <color
          rgba="0.75294 0.75294 0.75294 1" />
      </material>
    </visual>
    <collision>
      <origin
        xyz="0 0 0"
        rpy="0 0 0" />
      <geometry>
        <mesh
          filename="/home/taqiaden/GraspAgent/GraspAgent_2/kinematic_utils/cr7_speed/RFF_joint2_link.STL" />
      </geometry>
    </collision>
  </link>
  <joint
    name="RFF_joint2"
    type="revolute">
    <origin
      xyz="0 -0.044835 -0.0022002"
      rpy="0 0 0" />
    <parent
      link="RFF_joint1_link" />
    <child
      link="RFF_joint2_link" />
    <axis
      xyz="0 0 1" />
    <limit
      lower="0"
      upper="1.57"
      effort="0"
      velocity="0" />
  </joint>
  <link
    name="RFF_joint3_link">
    <inertial>
      <origin
        xyz="0.00022915 -0.017332 -0.0036024"
        rpy="0 0 0" />
      <mass
        value="0.0035954" />
      <inertia
        ixx="2.4321E-07"
        ixy="1.6638E-09"
        ixz="-9.0995E-13"
        iyy="9.6712E-08"
        iyz="2.4363E-11"
        izz="1.888E-07" />
    </inertial>
    <visual>
      <origin
        xyz="0 0 0"
        rpy="0 0 0" />
      <geometry>
        <mesh
          filename="/home/taqiaden/GraspAgent/GraspAgent_2/kinematic_utils/cr7_speed/RFF_joint3_link.STL" />
      </geometry>
      <material
        name="">
        <color
          rgba="0.75294 0.75294 0.75294 1" />
      </material>
    </visual>
    <collision>
      <origin
        xyz="0 0 0"
        rpy="0 0 0" />
      <geometry>
        <mesh
          filename="/home/taqiaden/GraspAgent/GraspAgent_2/kinematic_utils/cr7_speed/RFF_joint3_link.STL" />
      </geometry>
    </collision>
  </link>
  <joint
    name="RFF_joint3"
    type="revolute">
    <origin
      xyz="0.0019612 -0.024923 0.00010298"
      rpy="0 0 0" />
    <parent
      link="RFF_joint2_link" />
    <child
      link="RFF_joint3_link" />
    <axis
      xyz="0 0 1" />
    <limit
      lower="0"
      upper="1.57"
      effort="0"
      velocity="0" />
  </joint>
  <link
    name="RTh_joint1_link">
    <inertial>
      <origin
        xyz="-0.00052377 -0.019871 -0.0057348"
        rpy="0 0 0" />
      <mass
        value="0.0086971" />
      <inertia
        ixx="1.7729E-06"
        ixy="-5.2252E-08"
        ixz="2.8717E-10"
        iyy="5.6127E-07"
        iyz="6.3417E-09"
        izz="1.5998E-06" />
    </inertial>
    <visual>
      <origin
        xyz="0 0 0"
        rpy="0 0 0" />
      <geometry>
        <mesh
          filename="/home/taqiaden/GraspAgent/GraspAgent_2/kinematic_utils/cr7_speed/RTh_joint1_link.STL" />
      </geometry>
      <material
        name="">
        <color
          rgba="0.75294 0.75294 0.75294 1" />
      </material>
    </visual>
    <collision>
      <origin
        xyz="0 0 0"
        rpy="0 0 0" />
      <geometry>
        <mesh
          filename="/home/taqiaden/GraspAgent/GraspAgent_2/kinematic_utils/cr7_speed/RTh_joint1_link.STL" />
      </geometry>
    </collision>
  </link>
  <joint
    name="RTh_joint1"
    type="revolute">
    <origin
      xyz="0.02619  -0.05878   0.011385"
      rpy="-3.1416 0 -1.5708" />
    <parent
      link="hand_base_link" />
    <child
      link="RTh_joint1_link" />
    <axis
      xyz="0 0 1" />
    <limit
      lower="0"
      upper="1.57"
      effort="0"
      velocity="0" />
  </joint>
  <link
    name="RTh_joint2_link">
    <inertial>
      <origin
        xyz="0.001287 -0.012538 -0.0035807"
        rpy="0 0 0" />
      <mass
        value="0.0053861" />
      <inertia
        ixx="6.946E-07"
        ixy="5.1767E-08"
        ixz="-1.9989E-09"
        iyy="3.1014E-07"
        iyz="6.179E-09"
        izz="5.9235E-07" />
    </inertial>
    <visual>
      <origin
        xyz="0 0 0"
        rpy="0 0 0" />
      <geometry>
        <mesh
          filename="/home/taqiaden/GraspAgent/GraspAgent_2/kinematic_utils/cr7_speed/RTh_joint2_link.STL" />
      </geometry>
      <material
        name="">
        <color
          rgba="0.75294 0.75294 0.75294 1" />
      </material>
    </visual>
    <collision>
      <origin
        xyz="0 0 0"
        rpy="0 0 0" />
      <geometry>
        <mesh
          filename="/home/taqiaden/GraspAgent/GraspAgent_2/kinematic_utils/cr7_speed/RTh_joint2_link.STL" />
      </geometry>
    </collision>
  </link>
  <joint
    name="RTh_joint2"
    type="revolute">
    <origin
      xyz="0 -0.044835 -0.0022002"
      rpy="0 0 -0.011272" />
    <parent
      link="RTh_joint1_link" />
    <child
      link="RTh_joint2_link" />
    <axis
      xyz="0 0 1" />
    <limit
      lower="0"
      upper="1.57"
      effort="0"
      velocity="0" />
  </joint>
  <link
    name="RTh_joint3_link">
    <inertial>
      <origin
        xyz="0.00015718 -0.017333 -0.0036024"
        rpy="0 0 0" />
      <mass
        value="0.0035954" />
      <inertia
        ixx="2.4322E-07"
        ixy="1.0552E-09"
        ixz="-9.8987E-13"
        iyy="9.6701E-08"
        iyz="2.4593E-11"
        izz="1.888E-07" />
    </inertial>
    <visual>
      <origin
        xyz="0 0 0"
        rpy="0 0 0" />
      <geometry>
        <mesh
          filename="/home/taqiaden/GraspAgent/GraspAgent_2/kinematic_utils/cr7_speed/RTh_joint3_link.STL" />
      </geometry>
      <material
        name="">
        <color
          rgba="0.75294 0.75294 0.75294 1" />
      </material>
    </visual>
    <collision>
      <origin
        xyz="0 0 0"
        rpy="0 0 0" />
      <geometry>
        <mesh
          filename="/home/taqiaden/GraspAgent/GraspAgent_2/kinematic_utils/cr7_speed/RTh_joint3_link.STL" />
      </geometry>
    </collision>
  </link>
  <joint
    name="RTh_joint3"
    type="revolute">
    <origin
      xyz="0.0022421 -0.0249 0.00010298"
      rpy="0 0 0.015426" />
    <parent
      link="RTh_joint2_link" />
    <child
      link="RTh_joint3_link" />
    <axis
      xyz="0 0 1" />
    <limit
      lower="0"
      upper="1.57"
      effort="0"
      velocity="0" />
  </joint>
</robot>
