<mujoco model="URDF_speedhand_0618">

  <compiler angle="radian"/>
  <option integrator="implicitfast" cone="elliptic" noslip_iterations="5" noslip_tolerance="0"/>
  <default>
    <joint damping="0.01" armature="0.0001" frictionloss="0.01"/>
      <geom solref="0.02 0.8" solimp="0.9 0.95 0.001" friction="0.01 0.05 0.005"/>
  </default>
<size njmax="10000" nconmax="5000"/>

  <asset>
<!--      <texture name="skybox" type="skybox" builtin="flat" rgb1="1 1 1" width="64" height="64"/>-->
    <mesh name="base_link" file="base_link.STL"/>
    <mesh name="RFF-joint1-link" file="RFF-joint1-link.STL"/>
    <mesh name="RFF-joint2-link" file="RFF-joint2-link.STL"/>
    <mesh name="RFF-joint3-link" file="RFF-joint3-link.STL"/>
    <mesh name="tip" file="tip.STL"/>
    <mesh name="nail" file="nail.STL"/>
    <mesh name="j1_0" file="j1_0.stl"/>
    <mesh name="j1_1" file="j1_1.stl"/>
    <mesh name="j1_2" file="j1_2.stl"/>
    <mesh name="j1_3" file="j1_3.STL"/>
    <mesh name="j2_0" file="j2_0.stl"/>
    <mesh name="j2_1" file="j2_1.stl"/>
    <mesh name="j2_2" file="j2_2.stl"/>
    <mesh name="j2_3" file="j2_3.STL"/>
    <mesh name="j3_1" file="j3_1.stl"/>
    <mesh name="j3_2" file="j3_2.stl"/>
    <mesh name="part_0" file="part_0.stl"/>
    <mesh name="part_1" file="part_1.stl"/>
    <mesh name="part_2" file="part_2.stl"/>
    <mesh name="part_3" file="part_3.stl"/>
    <mesh name="part_5" file="part_5.stl"/>
    <mesh name="part_11" file="part_11.stl"/>
    <mesh name="part_12" file="part_12.stl"/>
    <mesh name="part_15" file="part_15.stl"/>
    <mesh name="part_18" file="part_18.stl"/>
  </asset>

<extension>

  <plugin plugin="mujoco.pid">
    <instance name="pid_RTh">
        <config key="kp" value="32"/>
        <config key="ki" value="4.0"/>
        <config key="kd" value="0.1"/>
        <config key="imax" value="0.2"/>
        <config key="slewmax" value="6.28318"/>
    </instance>
  </plugin>

  <plugin plugin="mujoco.pid">
    <instance name="pid_RFF">
        <config key="kp" value="8"/>
        <config key="ki" value="4.0"/>
        <config key="kd" value="0.1"/>
        <config key="imax" value="0.2"/>
        <config key="slewmax" value="6.28318"/>
    </instance>
  </plugin>

  <plugin plugin="mujoco.pid">
    <instance name="pid_RMF">
        <config key="kp" value="8"/>
        <config key="ki" value="4.0"/>
        <config key="kd" value="0.1"/>
        <config key="imax" value="0.2"/>
        <config key="slewmax" value="6.28318"/>
    </instance>
  </plugin>

  <plugin plugin="mujoco.pid">
    <instance name="pid_RRF">
        <config key="kp" value="8"/>
        <config key="ki" value="4.0"/>
        <config key="kd" value="0.1"/>
        <config key="imax" value="0.2"/>
        <config key="slewmax" value="6.28318"/>
    </instance>
  </plugin>

  <plugin plugin="mujoco.pid">
    <instance name="pid_RLF">
        <config key="kp" value="8"/>
        <config key="ki" value="4.0"/>
        <config key="kd" value="0.1"/>
        <config key="imax" value="0.2"/>
        <config key="slewmax" value="6.28318"/>
    </instance>
  </plugin>

</extension>

  <worldbody>
    <body name="tcp">
      <freejoint/>
      <body name="translate" pos="-0.08 0.14 -0.02">
        <body gravcomp="1" name="base" pos="-0.204141 0.242939 -0.004">
          <geom type="mesh" rgba="0.752941 0.752941 0.752941 1" mesh="base_link" contype="0" conaffinity="0" group="0"/>
          <geom type="mesh" rgba="0.752941 0.752941 0.752941 0" mesh="part_0" mass="0" name="pad1"/>
          <geom type="mesh" rgba="0.752941 0.752941 0.752941 0" mesh="part_1" mass="0" name="pad2"/>
          <geom type="mesh" rgba="0.752941 0.752941 0.752941 0" mesh="part_2" mass="0" name="pad3"/>
          <geom type="mesh" rgba="0.752941 0.752941 0.752941 0" mesh="part_3" group="3" mass="0"/>
          <geom type="mesh" rgba="0.752941 0.752941 0.752941 0" mesh="part_5" group="3" mass="0"/>
          <geom type="mesh" rgba="0.752941 0.752941 0.752941 0" mesh="part_11" group="3" mass="0"/>
          <geom type="mesh" rgba="0.752941 0.752941 0.752941 0" mesh="part_12" group="3" mass="0"/>
          <geom type="mesh" rgba="0.752941 0.752941 0.752941 0" mesh="part_15" group="3" mass="0"/>
          <geom type="mesh" rgba="0.752941 0.752941 0.752941 0" mesh="part_18" group="3" mass="0"/>

          <body gravcomp="1" name="RTh-joint1-link" pos="0.23099 -0.29978 0.017385" quat="-2.59734e-06 -0.707105 0.707108 2.59735e-06" >
            <inertial pos="-0.00052377 -0.019871 -0.0057348" quat="0.709096 0.704783 -0.0151904 -0.0152259" mass="0.0086971" diaginertia="1.77515e-06 1.59984e-06 5.58982e-07"/>
            <joint name="RTh-joint1" pos="0 0 0" axis="0 0 1" range="0 0.57"    />
            <geom type="mesh" rgba="0.752941 0.752941 0.752941 1" mesh="RFF-joint1-link" contype="0" conaffinity="0" group="0"/>
            <geom type="mesh"  rgba="0.035  0.586 0.953 1" name="ft1_a" mesh="j1_0" mass="0"/>
            <geom type="mesh"  rgba="0.752941 0.752941 0.752941 1" mesh="j1_1" mass="0" group="3"/>
            <geom type="mesh"  rgba="0.752941 0.752941 0.752941 1" mesh="j1_2" mass="0" group="3"/>
            <geom type="mesh"  rgba="0.752941 0.752941 0.752941 1" mesh="j1_3" mass="0" group="3"/>
            <body gravcomp="1" name="RTh-joint2-link" pos="0 -0.044835 -0.0022002" quat="0.999984 0 0 -0.00563597">
              <inertial pos="0.001287 -0.012538 -0.0035807" quat="0.713567 0.697486 0.0497241 0.0431685" mass="0.0053861" diaginertia="7.01461e-07 5.92479e-07 3.03151e-07"/>
              <joint name="RTh-joint2" pos="0 0 0" axis="0 0 1" range="0 1.57"  />
              <geom type="mesh" rgba="0.752941 0.752941 0.752941 1" mesh="RFF-joint2-link" contype="0" conaffinity="0" group="0"/>
              <geom type="mesh"  rgba="0.035  0.586 0.953 1" name="ft1_b" mesh="j2_0" mass="0"/>
              <geom type="mesh"  rgba="0.752941 0.752941 0.752941 1" mesh="j2_1" mass="0" group="3"/>
              <geom type="mesh"  rgba="0.752941 0.752941 0.752941 1" mesh="j2_2" mass="0" group="3"/>
              <geom type="mesh"  rgba="0.752941 0.752941 0.752941 1" mesh="j2_3" mass="0" group="3"/>
              <body gravcomp="1" name="RTh-joint3-link" pos="0.0022421 -0.0249 0.00010298" quat="0.99997 0 0 0.00771292">
                <inertial pos="0.00015718 -0.017333 -0.0036024" quat="0.707197 0.707008 0.0025457 0.00254638" mass="0.0035954" diaginertia="2.43228e-07 1.888e-07 9.66934e-08"/>
                <joint name="RTh-joint3" pos="0 0 0" axis="0 0 1" range="0 1.57"  />
                <geom type="mesh" rgba="0.752941 0.752941 0.752941 1" mesh="RFF-joint3-link" contype="0" conaffinity="0" group="0"/>
                <geom type="mesh" rgba="0.035  0.586 0.953 1" mesh="tip" name="ft1" mass="0"/>
                <geom type="mesh" rgba="0.035  0.586 0.953 1" mesh="j3_1" name="ft1_c" mass="0"/>
                <geom type="mesh" rgba="0.752941 0.752941 0.752941 1" mesh="j3_2" mass="0" group="3"/>
              </body>
            </body>
          </body>

          <body gravcomp="1" name="RFF-joint1-link" pos="0.19574 -0.37808 0.040085" quat="0.999848 -0.0174526 0 0" >
            <inertial pos="-0.00052376 -0.019871 -0.0057348" quat="0.709096 0.704783 -0.0151894 -0.0152269" mass="0.0086971" diaginertia="1.77515e-06 1.59984e-06 5.58982e-07"/>
            <joint name="RFF-joint1" pos="0 0 0" axis="0 0 1" range="0  1.3"   />
            <geom type="mesh" rgba="0.752941 0.752941 0.752941 1" mesh="RFF-joint1-link" contype="0" conaffinity="0" group="0"/>
            <geom type="mesh"  rgba="0.035  0.586 0.953 1" name="ft2_a" mesh="j1_0" mass="0"/>
            <geom type="mesh"  rgba="0.752941 0.752941 0.752941 1" mesh="j1_1" mass="0" group="3"/>
            <geom type="mesh"  rgba="0.752941 0.752941 0.752941 1" mesh="j1_2" mass="0" group="3"/>
            <geom type="mesh"  rgba="0.752941 0.752941 0.752941 1" mesh="j1_3" mass="0" group="3"/>
            <body gravcomp="1" name="RFF-joint2-link" pos="0 -0.044835 -0.0022002" quat="0.999984 0 0 -0.00563597">
              <inertial pos="0.001287 -0.012538 -0.0035807" quat="0.713567 0.697486 0.0497241 0.0431685" mass="0.0053861" diaginertia="7.01461e-07 5.92479e-07 3.03151e-07"/>
              <joint name="RFF-joint2" pos="0 0 0" axis="0 0 1" range="0 1.57"  />
              <geom type="mesh" rgba="0.752941 0.752941 0.752941 1" mesh="RFF-joint2-link" contype="0" conaffinity="0" group="0"/>
              <geom type="mesh"  rgba="0.035  0.586 0.953 1" name="ft2_b" mesh="j2_0" mass="0"/>
              <geom type="mesh"  rgba="0.752941 0.752941 0.752941 1" mesh="j2_1" mass="0" group="3"/>
              <geom type="mesh"  rgba="0.752941 0.752941 0.752941 1" mesh="j2_2" mass="0" group="3"/>
              <geom type="mesh"  rgba="0.752941 0.752941 0.752941 1" mesh="j2_3" mass="0" group="3"/>
              <body gravcomp="1" name="RFF-joint3-link" pos="0.0022421 -0.0249 0.00010298" quat="0.99997 0 0 0.00771292">
                <inertial pos="0.00015718 -0.017333 -0.0036024" quat="0.707197 0.707008 0.0025457 0.00254638" mass="0.0035954" diaginertia="2.43228e-07 1.888e-07 9.66934e-08"/>
                <joint name="RFF-joint3" pos="0 0 0" axis="0 0 1" range="0 1.57"  />
                <geom type="mesh" rgba="0.752941 0.752941 0.752941 1" mesh="RFF-joint3-link" contype="0" conaffinity="0" group="0"/>
                <geom type="mesh" rgba="0.035  0.586 0.953 1" mesh="tip" name="ft2" mass="0"/>
                <geom type="mesh" rgba="0.035  0.586 0.953 1" mesh="j3_1" name="ft2_c" mass="0"/>
                <geom type="mesh" rgba="0.752941 0.752941 0.752941 1" mesh="j3_2" mass="0" group="3"/>
              </body>
            </body>
          </body>

          <body gravcomp="1" name="RMF-joint1-link" pos="0.19574 -0.38138 0.0167">
            <inertial pos="-0.00052376 -0.019871 -0.0057348" quat="0.709096 0.704783 -0.0151894 -0.0152269" mass="0.0086971" diaginertia="1.77515e-06 1.59984e-06 5.58982e-07"/>
            <joint name="RMF-joint1" pos="0 0 0" axis="0 0 1" range="0  1.3"  />
            <geom type="mesh" rgba="0.752941 0.752941 0.752941 1" mesh="RFF-joint1-link" contype="0" conaffinity="0" group="0"/>
            <geom type="mesh"  rgba="0.035  0.586 0.953 1" name="ft3_a" mesh="j1_0" mass="0"/>
            <geom type="mesh"  rgba="0.752941 0.752941 0.752941 1" mesh="j1_1" mass="0" group="3"/>
            <geom type="mesh"  rgba="0.752941 0.752941 0.752941 1" mesh="j1_2" mass="0" group="3"/>
            <geom type="mesh"  rgba="0.752941 0.752941 0.752941 1" mesh="j1_3" mass="0" group="3"/>
            <body gravcomp="1" name="RMF-joint2-link" pos="0 -0.044835 -0.0022002" quat="0.999984 0 0 -0.00563597">
              <inertial pos="0.001287 -0.012538 -0.0035807" quat="0.713567 0.697486 0.0497241 0.0431685" mass="0.0053861" diaginertia="7.01461e-07 5.92479e-07 3.03151e-07"/>
              <joint name="RMF-joint2" pos="0 0 0" axis="0 0 1" range="0 1.57"  />
              <geom type="mesh" rgba="0.752941 0.752941 0.752941 1" mesh="RFF-joint2-link" contype="0" conaffinity="0" group="0"/>
              <geom type="mesh"  rgba="0.035  0.586 0.953 1" name="ft3_b" mesh="j2_0" mass="0"/>
              <geom type="mesh"  rgba="0.752941 0.752941 0.752941 1" mesh="j2_1" mass="0" group="3"/>
              <geom type="mesh"  rgba="0.752941 0.752941 0.752941 1" mesh="j2_2" mass="0" group="3"/>
              <geom type="mesh"  rgba="0.752941 0.752941 0.752941 1" mesh="j2_3" mass="0" group="3"/>
              <body gravcomp="1" name="RMF-joint3-link" pos="0.0022421 -0.0249 0.00010298" quat="0.99997 0 0 0.00771292">
                <inertial pos="0.00015718 -0.017333 -0.0036024" quat="0.707197 0.707008 0.0025457 0.00254638" mass="0.0035954" diaginertia="2.43228e-07 1.888e-07 9.66934e-08"/>
                <joint name="RMF-joint3" pos="0 0 0" axis="0 0 1" range="0 1.57"    />
                <geom type="mesh" rgba="0.752941 0.752941 0.752941 1" mesh="RFF-joint3-link" contype="0" conaffinity="0" group="0"/>
                <geom type="mesh" rgba="0.035  0.586 0.953 1" mesh="tip" name="ft3" mass="0"/>
                <geom type="mesh" rgba="0.035  0.586 0.953 1" mesh="j3_1" name="ft3_c" mass="0"/>
                <geom type="mesh" rgba="0.752941 0.752941 0.752941 1" mesh="j3_2" mass="0" group="3"/>
              </body>
            </body>
          </body>

          <body gravcomp="1" name="RRF-joint1-link" pos="0.19574 -0.3767 -0.0061806" quat="0.999848 0.0174526 0 0" >
            <inertial pos="-0.00052377 -0.019871 -0.0057348" quat="0.709096 0.704784 -0.0151898 -0.0152265" mass="0.0086971" diaginertia="1.77515e-06 1.59984e-06 5.58982e-07"/>
            <joint name="RRF-joint1" pos="0 0 0" axis="0 0 1" range="0  1.3"   />
            <geom type="mesh" rgba="0.752941 0.752941 0.752941 1" mesh="RFF-joint1-link" contype="0" conaffinity="0" group="0"/>
            <geom type="mesh"  rgba="0.035  0.586 0.953 1" name="ft4_a" mesh="j1_0" mass="0"/>
            <geom type="mesh"  rgba="0.752941 0.752941 0.752941 1" mesh="j1_1" mass="0" group="3"/>
            <geom type="mesh"  rgba="0.752941 0.752941 0.752941 1" mesh="j1_2" mass="0" group="3"/>
            <geom type="mesh"  rgba="0.752941 0.752941 0.752941 1" mesh="j1_3" mass="0" group="3"/>
            <body gravcomp="1" name="RRF-joint2-link" pos="0 -0.044835 -0.0022002" quat="0.999984 0 0 -0.00563597">
              <inertial pos="0.001287 -0.012538 -0.0035807" quat="0.713567 0.697486 0.0497241 0.0431685" mass="0.0053861" diaginertia="7.01461e-07 5.92479e-07 3.03151e-07"/>
              <joint name="RRF-joint2" pos="0 0 0" axis="0 0 1" range="0 1.57"  />
              <geom type="mesh" rgba="0.752941 0.752941 0.752941 1" mesh="RFF-joint2-link" contype="0" conaffinity="0" group="0"/>
              <geom type="mesh"  rgba="0.035  0.586 0.953 1" name="ft4_b" mesh="j2_0" mass="0"/>
              <geom type="mesh"  rgba="0.752941 0.752941 0.752941 1" mesh="j2_1" mass="0" group="3"/>
              <geom type="mesh"  rgba="0.752941 0.752941 0.752941 1" mesh="j2_2" mass="0" group="3"/>
              <geom type="mesh"  rgba="0.752941 0.752941 0.752941 1" mesh="j2_3" mass="0" group="3"/>
              <body gravcomp="1" name="RRF-joint3-link" pos="0.0022421 -0.0249 0.00010298" quat="0.99997 0 0 0.00771292">
                <inertial pos="0.00015718 -0.017333 -0.0036024" quat="0.707197 0.707008 0.0025457 0.00254638" mass="0.0035954" diaginertia="2.43228e-07 1.888e-07 9.66934e-08"/>
                <joint name="RRF-joint3" pos="0 0 0" axis="0 0 1" range="0 1.57"  />
                <geom type="mesh" rgba="0.752941 0.752941 0.752941 1" mesh="RFF-joint3-link" contype="0" conaffinity="0" group="0"/>
                <geom type="mesh" rgba="0.035  0.586 0.953 1" mesh="tip" name="ft4" mass="0"/>
                <geom type="mesh" rgba="0.035  0.586 0.953 1" mesh="j3_1" name="ft4_c" mass="0"/>
                <geom type="mesh" rgba="0.752941 0.752941 0.752941 1" mesh="j3_2" mass="0" group="3"/>
              </body>
            </body>
          </body>

          <body gravcomp="1" name="RLF-joint1-link" pos="0.19574 -0.3724 -0.030054" quat="0.999391 0.0348994 0 0" >
            <inertial pos="-0.00052376 -0.019871 -0.0057348" quat="0.709096 0.704784 -0.0151885 -0.0152278" mass="0.0086971" diaginertia="1.77515e-06 1.59984e-06 5.58982e-07"/>
            <joint name="RLF-joint1" pos="0 0 0" axis="0 0 1" range="0  1.3"  />
            <geom type="mesh" rgba="0.752941 0.752941 0.752941 1" mesh="RFF-joint1-link" contype="0" conaffinity="0" group="0"/>
            <geom type="mesh"  rgba="0.035  0.586 0.953 1" name="ft5_a" mesh="j1_0" mass="0"/>
            <geom type="mesh"  rgba="0.752941 0.752941 0.752941 1" mesh="j1_1" mass="0" group="3"/>
            <geom type="mesh"  rgba="0.752941 0.752941 0.752941 1" mesh="j1_2" mass="0" group="3"/>
            <geom type="mesh"  rgba="0.752941 0.752941 0.752941 1" mesh="j1_3" mass="0" group="3"/>
            <body gravcomp="1" name="RLF-joint2-link" pos="0 -0.044835 -0.0022002" quat="0.999984 0 0 -0.00563597">
              <inertial pos="0.001287 -0.012538 -0.0035807" quat="0.713567 0.697486 0.0497241 0.0431685" mass="0.0053861" diaginertia="7.01461e-07 5.92479e-07 3.03151e-07"/>
              <joint name="RLF-joint2" pos="0 0 0" axis="0 0 1" range="0 1.57"   />
              <geom type="mesh" rgba="0.752941 0.752941 0.752941 1" mesh="RFF-joint2-link" contype="0" conaffinity="0" group="0"/>
              <geom type="mesh"  rgba="0.035  0.586 0.953 1" name="ft5_b" mesh="j2_0" mass="0"/>
              <geom type="mesh"  rgba="0.752941 0.752941 0.752941 1" mesh="j2_1" mass="0" group="3"/>
              <geom type="mesh"  rgba="0.752941 0.752941 0.752941 1" mesh="j2_2" mass="0" group="3"/>
              <geom type="mesh"  rgba="0.752941 0.752941 0.752941 1" mesh="j2_3" mass="0" group="3"/>
              <body gravcomp="1" name="RLF-joint3-link" pos="0.0022421 -0.0249 0.00010298" quat="0.99997 0 0 0.00771292">
                <inertial pos="0.00015718 -0.017333 -0.0036024" quat="0.707197 0.707008 0.0025457 0.00254638" mass="0.0035954" diaginertia="2.43228e-07 1.888e-07 9.66934e-08"/>
                <joint name="RLF-joint3" pos="0 0 0" axis="0 0 1" range="0 1.57"  />
                <geom type="mesh" rgba="0.752941 0.752941 0.752941 1" mesh="RFF-joint3-link" contype="0" conaffinity="0" group="0"/>
                <geom type="mesh" rgba="0.035  0.586 0.953 1" mesh="tip" name="ft5" mass="0"/>
                <geom type="mesh" rgba="0.035  0.586 0.953 1" mesh="j3_1" name="ft5_c" mass="0"/>
                <geom type="mesh" rgba="0.752941 0.752941 0.752941 1" mesh="j3_2" mass="0" group="3"/>
              </body>
            </body>
          </body>
        </body>
      </body>
    </body>
    <body gravcomp="1" mocap="true" name="mocap" pos="0 0 0">
<!--      <geom conaffinity="0" contype="0" pos="0 0 0" rgba="0 0.5 0 0.7" size="0.005 0.005 0.005" type="box"></geom>-->
<!--      <geom conaffinity="0" contype="0" pos="0.1 0 0" rgba="1 0 0 0.3" size="0.1 0.005 0.005" type="box"></geom>-->
<!--      <geom conaffinity="0" contype="0" pos="0 0.1 0" rgba="0.035  0.586 0.953 1" size="0.005 0.1 0.005" type="box"></geom>-->
<!--      <geom conaffinity="0" contype="0" pos="0 0 0.3" rgba="0.035  0.586 0.953 1" size="0.005 0.005 0.3" type="box"></geom>-->
    </body>
  </worldbody>

 <actuator>

  <plugin name="RTh_act"
          plugin="mujoco.pid"
          instance="pid_RTh"
          joint="RTh-joint1"
          ctrlrange="0 1.5"
          forcerange="-3 3"
          dyntype="none"
          actdim="2"/>

  <plugin name="RFF_act"
          plugin="mujoco.pid"
          instance="pid_RFF"
          joint="RFF-joint1"
          ctrlrange="0 1.5"
          forcerange="-1.5 1.5"
          dyntype="none"
          actdim="2"/>

  <plugin name="RMF_act"
          plugin="mujoco.pid"
          instance="pid_RMF"
          joint="RMF-joint1"
          ctrlrange="0 1.5"
          forcerange="-1.5 1.5"
          dyntype="none"
          actdim="2"/>

  <plugin name="RRF_act"
          plugin="mujoco.pid"
          instance="pid_RRF"
          joint="RRF-joint1"
          ctrlrange="0 1.5"
          forcerange="-1.5 1.5"
          dyntype="none"
          actdim="2"/>

  <plugin name="RLF_act"
          plugin="mujoco.pid"
          instance="pid_RLF"
          joint="RLF-joint1"
          ctrlrange="0 1.3"
          forcerange="-1.5 1.5"
          dyntype="none"
          actdim="2"/>
</actuator>

  <contact>
    <exclude body1="RFF-joint1-link" body2="base"/>
    <exclude body1="RLF-joint1-link" body2="base"/>
    <exclude body1="RRF-joint1-link" body2="base"/>
    <exclude body1="RMF-joint1-link" body2="base"/>
    <exclude body1="RTh-joint1-link" body2="base"/>
  </contact>

  <equality>
    <weld body1="mocap" body2="tcp"  solref="0.01 1" solimp="0.9 0.99 0.001" />

      <!-- Thumb -->
  <joint joint2="RTh-joint1" joint1="RTh-joint2" polycoef="0 0.5 0 0 0"/>
  <joint joint2="RTh-joint1" joint1="RTh-joint3" polycoef="0 0.2 0 0 0"/>

  <!-- Index -->
  <joint joint2="RFF-joint1" joint1="RFF-joint2" polycoef="0 0.4 0 0 0"/>
  <joint joint2="RFF-joint1" joint1="RFF-joint3" polycoef="0 0.1 0 0 0"/>

  <!-- Middle -->
  <joint joint2="RMF-joint1" joint1="RMF-joint2" polycoef="0 0.4 0 0 0"/>
  <joint joint2="RMF-joint1" joint1="RMF-joint3" polycoef="0 0.1 0 0 0"/>

  <!-- Ring -->
  <joint joint2="RRF-joint1" joint1="RRF-joint2" polycoef="0 0.4 0 0 0"/>
  <joint joint2="RRF-joint1" joint1="RRF-joint3" polycoef="0 0.1 0 0 0"/>

  <!-- Little -->
  <joint joint2="RLF-joint1" joint1="RLF-joint2" polycoef="0 0.4 0 0 0"/>
  <joint joint2="RLF-joint1" joint1="RLF-joint3" polycoef="0 0.1 0 0 0"/>

  </equality>

</mujoco>